<?xml version='1.0' encoding='utf-8'?>
<robot name="walker_s2_official">
  <link name="base_link">
    <inertial>
      <origin xyz="-0.06386519 -0.00011351 0.01065255" rpy="0 0 0" />
      <mass value="6.10566795" />
      <inertia ixx="0.05624802" ixy="-2.68E-05" ixz="-0.00443226" iyy="0.02883251" iyz="-0.000134" izz="0.07296666" />
      </inertial>
    <visual>
      <origin xyz="0 0 0" rpy="0 0 0" />
      <geometry>
        <mesh filename="meshes/base_link.STL" />
        </geometry>
      <material name="base_link_visual_material_0">
        <color rgba="1 1 1 1" />
        </material>
      </visual>
    <collision>
      <origin xyz="0 0 0" rpy="0 0 0" />
      <geometry>
        <mesh filename="meshes/base_link.STL" />
        </geometry>
      </collision>
    </link>
  <link name="waist_yaw_link">
    <inertial>
      <origin xyz="-0.00019894 -0.0096767 0.02710775" rpy="0 0 0" />
      <mass value="0.51683988" />
      <inertia ixx="0.00171935" ixy="2.37E-06" ixz="9.57E-06" iyy="0.00108364" iyz="-6.49E-05" izz="0.00138793" />
      </inertial>
    <visual>
      <origin xyz="0 0 0" rpy="0 0 0" />
      <geometry>
        <mesh filename="meshes/waist_yaw_link.STL" />
        </geometry>
      <material name="waist_yaw_link_visual_material_1">
        <color rgba="1 1 1 1" />
        </material>
      </visual>
    <collision>
      <origin xyz="0 0 0" rpy="0 0 0" />
      <geometry>
        <mesh filename="meshes/waist_yaw_link.STL" />
        </geometry>
      </collision>
    </link>
  <link name="waist_pitch_link">
    <inertial>
      <origin xyz="-0.0173718 0.2054213 -0.00210714" rpy="0 0 0" />
      <mass value="24.18588597" />
      <inertia ixx="0.52254924" ixy="0.0122" ixz="0.00245568" iyy="0.20002449" iyz="-0.00535" izz="0.4671002" />
      </inertial>
    <visual>
      <origin xyz="0 0 0" rpy="0 0 0" />
      <geometry>
        <mesh filename="meshes/waist_pitch_link.STL" />
        </geometry>
      <material name="waist_pitch_link_visual_material_2">
        <color rgba="1 1 1 1" />
        </material>
      </visual>
    <collision>
      <origin xyz="0 0 0" rpy="0 0 0" />
      <geometry>
        <mesh filename="meshes/waist_pitch_link.STL" />
        </geometry>
      </collision>
    </link>
  <link name="head_yaw_link">
    <inertial>
      <origin xyz="0.00023349 -3.98E-05 0.02308052" rpy="0 0 0" />
      <mass value="0.21951531" />
      <inertia ixx="8.12E-05" ixy="1.01E-06" ixz="-3.2E-07" iyy="6.29E-05" iyz="3.78E-06" izz="7.63E-05" />
      </inertial>
    <visual>
      <origin xyz="0 0 0" rpy="0 0 0" />
      <geometry>
        <mesh filename="meshes/head_yaw_link.STL" />
        </geometry>
      <material name="head_yaw_link_visual_material_3">
        <color rgba="1 1 1 1" />
        </material>
      </visual>
    <collision>
      <origin xyz="0 0 0" rpy="0 0 0" />
      <geometry>
        <mesh filename="meshes/head_yaw_link.STL" />
        </geometry>
      </collision>
    </link>
  <link name="head_pitch_link">
    <inertial>
      <origin xyz="0.04056552 0.10249693 -0.00026038" rpy="0 0 0" />
      <mass value="1.0690069" />
      <inertia ixx="0.00473535" ixy="0.00033437" ixz="-1.26E-05" iyy="0.00450809" iyz="-2.68E-05" izz="0.00518573" />
      </inertial>
    <visual>
      <origin xyz="0 0 0" rpy="0 0 0" />
      <geometry>
        <mesh filename="meshes/head_pitch_link.STL" />
        </geometry>
      <material name="head_pitch_link_visual_material_4">
        <color rgba="1 1 1 1" />
        </material>
      </visual>
    <collision>
      <origin xyz="0 0 0" rpy="0 0 0" />
      <geometry>
        <mesh filename="meshes/head_pitch_link.STL" />
        </geometry>
      </collision>
    </link>
  <link name="L_shoulder_pitch_link">
    <inertial>
      <origin xyz="0.000221 -0.00509318 -0.05262953" rpy="0 0 0" />
      <mass value="0.98147022" />
      <inertia ixx="0.00117594" ixy="-4.84E-06" ixz="-2.41E-06" iyy="0.00112373" iyz="-3.12E-05" izz="0.00090041" />
      </inertial>
    <visual>
      <origin xyz="0 0 0" rpy="0 0 0" />
      <geometry>
        <mesh filename="meshes/L_shoulder_pitch_link.STL" />
        </geometry>
      <material name="L_shoulder_pitch_link_visual_material_5">
        <color rgba="1 1 1 1" />
        </material>
      </visual>
    <collision>
      <origin xyz="0 0 0" rpy="0 0 0" />
      <geometry>
        <mesh filename="meshes/L_shoulder_pitch_link.STL" />
        </geometry>
      </collision>
    </link>
  <link name="L_shoulder_roll_link">
    <inertial>
      <origin xyz="-0.0363463 0.00197513 -0.00526968" rpy="0 0 0" />
      <mass value="0.53957013" />
      <inertia ixx="0.00123053" ixy="-1.9E-05" ixz="0.000107" iyy="0.00189152" iyz="-1.3E-05" izz="0.00142983" />
      </inertial>
    <visual>
      <origin xyz="0 0 0" rpy="0 0 0" />
      <geometry>
        <mesh filename="meshes/L_shoulder_roll_link.STL" />
        </geometry>
      <material name="L_shoulder_roll_link_visual_material_6">
        <color rgba="1 1 1 1" />
        </material>
      </visual>
    <collision>
      <origin xyz="0 0 0" rpy="0 0 0" />
      <geometry>
        <mesh filename="meshes/L_shoulder_roll_link.STL" />
        </geometry>
      </collision>
    </link>
  <link name="L_shoulder_yaw_link">
    <inertial>
      <origin xyz="-0.00899004 0.00278 0.12860192" rpy="0 0 0" />
      <mass value="1.99759468" />
      <inertia ixx="0.01565644" ixy="5.4E-05" ixz="0.00156529" iyy="0.01576798" iyz="-0.000436" izz="0.00210574" />
      </inertial>
    <visual>
      <origin xyz="0 0 0" rpy="0 0 0" />
      <geometry>
        <mesh filename="meshes/L_shoulder_yaw_link.STL" />
        </geometry>
      <material name="L_shoulder_yaw_link_visual_material_7">
        <color rgba="1 1 1 1" />
        </material>
      </visual>
    <collision>
      <origin xyz="0 0 0" rpy="0 0 0" />
      <geometry>
        <mesh filename="meshes/L_shoulder_yaw_link.STL" />
        </geometry>
      </collision>
    </link>
  <link name="L_elbow_roll_link">
    <inertial>
      <origin xyz="0.00853041 -0.05741022 0.00089275" rpy="0 0 0" />
      <mass value="0.66750304" />
      <inertia ixx="0.00253838" ixy="0.00030611" ixz="7.49E-06" iyy="0.00139512" iyz="-3.35E-05" izz="0.00220496" />
      </inertial>
    <visual>
      <origin xyz="0 0 0" rpy="0 0 0" />
      <geometry>
        <mesh filename="meshes/L_elbow_roll_link.STL" />
        </geometry>
      <material name="L_elbow_roll_link_visual_material_8">
        <color rgba="1 1 1 1" />
        </material>
      </visual>
    <collision>
      <origin xyz="0 0 0" rpy="0 0 0" />
      <geometry>
        <mesh filename="meshes/L_elbow_roll_link.STL" />
        </geometry>
      </collision>
    </link>
  <link name="L_elbow_yaw_link">
    <inertial>
      <origin xyz="0.00097407 0.00017933 0.04577716" rpy="0 0 0" />
      <mass value="0.87457488" />
      <inertia ixx="0.00143841" ixy="3.89E-06" ixz="-5.22E-05" iyy="0.0016363" iyz="7E-07" izz="0.00087583" />
      </inertial>
    <visual>
      <origin xyz="0 0 0" rpy="0 0 0" />
      <geometry>
        <mesh filename="meshes/L_elbow_yaw_link.STL" />
        </geometry>
      <material name="L_elbow_yaw_link_visual_material_9">
        <color rgba="1 1 1 1" />
        </material>
      </visual>
    <collision>
      <origin xyz="0 0 0" rpy="0 0 0" />
      <geometry>
        <mesh filename="meshes/L_elbow_yaw_link.STL" />
        </geometry>
      </collision>
    </link>
  <link name="L_wrist_pitch_link">
    <inertial>
      <origin xyz="-0.03844459 -0.00485589 -0.00477205" rpy="0 0 0" />
      <mass value="1.31445091" />
      <inertia ixx="0.00090036" ixy="-0.00021851" ixz="0.000227" iyy="0.00273144" iyz="3.05E-05" izz="0.00273579" />
      </inertial>
    <visual>
      <origin xyz="0 0 0" rpy="0 0 0" />
      <geometry>
        <mesh filename="meshes/L_wrist_pitch_link.STL" />
        </geometry>
      <material name="L_wrist_pitch_link_visual_material_10">
        <color rgba="1 1 1 1" />
        </material>
      </visual>
    <collision>
      <origin xyz="0 0 0" rpy="0 0 0" />
      <geometry>
        <mesh filename="meshes/L_wrist_pitch_link.STL" />
        </geometry>
      </collision>
    </link>
  <link name="L_wrist_roll_link">
    <inertial>
      <origin xyz="-4.59E-06 0.0170564 -0.0007487" rpy="0 0 0" />
      <mass value="0.15210234" />
      <inertia ixx="0.00027356" ixy="0" ixz="-2E-08" iyy="0.00021546" iyz="-7.68E-06" izz="0.00011023" />
      </inertial>
    <visual>
      <origin xyz="0 0 0" rpy="0 0 0" />
      <geometry>
        <mesh filename="meshes/L_wrist_roll_link.STL" />
        </geometry>
      <material name="L_wrist_roll_link_visual_material_11">
        <color rgba="1 1 1 1" />
        </material>
      </visual>
    <collision>
      <origin xyz="0 0 0" rpy="0 0 0" />
      <geometry>
        <mesh filename="meshes/L_wrist_roll_link.STL" />
        </geometry>
      </collision>
    </link>
  <link name="L_sixforce_link">
    <inertial>
      <origin xyz="0.00018615 2.11E-06 -0.01106561" rpy="0 0 0" />
      <mass value="0.16999999" />
      <inertia ixx="3.57E-05" ixy="2.1E-07" ixz="-7.8E-07" iyy="5.03E-05" iyz="6E-08" izz="6.13E-05" />
      </inertial>
    <visual>
      <origin xyz="0 0 0" rpy="0 0 0" />
      <geometry>
        <mesh filename="meshes/L_sixforce_link.STL" />
        </geometry>
      <material name="L_sixforce_link_visual_material_12">
        <color rgba="1 1 1 1" />
        </material>
      </visual>
    <collision>
      <origin xyz="0 0 0" rpy="0 0 0" />
      <geometry>
        <mesh filename="meshes/L_sixforce_link.STL" />
        </geometry>
      </collision>
    </link>
  <link name="R_shoulder_pitch_link">
    <inertial>
      <origin xyz="-8.87E-05 0.00504437 -0.05262341" rpy="0 0 0" />
      <mass value="0.98272939" />
      <inertia ixx="0.00117784" ixy="-5.21E-06" ixz="-4.64E-06" iyy="0.00112441" iyz="3.15E-05" izz="0.00090287" />
      </inertial>
    <visual>
      <origin xyz="0 0 0" rpy="0 0 0" />
      <geometry>
        <mesh filename="meshes/R_shoulder_pitch_link.STL" />
        </geometry>
      <material name="R_shoulder_pitch_link_visual_material_13">
        <color rgba="1 1 1 1" />
        </material>
      </visual>
    <collision>
      <origin xyz="0 0 0" rpy="0 0 0" />
      <geometry>
        <mesh filename="meshes/R_shoulder_pitch_link.STL" />
        </geometry>
      </collision>
    </link>
  <link name="R_shoulder_roll_link">
    <inertial>
      <origin xyz="-0.03609145 0.00196617 0.00534494" rpy="0 0 0" />
      <mass value="0.54339959" />
      <inertia ixx="0.00124605" ixy="-1.87E-05" ixz="-0.000109" iyy="0.00191195" iyz="1.3E-05" izz="0.00143677" />
      </inertial>
    <visual>
      <origin xyz="0 0 0" rpy="0 0 0" />
      <geometry>
        <mesh filename="meshes/R_shoulder_roll_link.STL" />
        </geometry>
      <material name="R_shoulder_roll_link_visual_material_14">
        <color rgba="1 1 1 1" />
        </material>
      </visual>
    <collision>
      <origin xyz="0 0 0" rpy="0 0 0" />
      <geometry>
        <mesh filename="meshes/R_shoulder_roll_link.STL" />
        </geometry>
      </collision>
    </link>
  <link name="R_shoulder_yaw_link">
    <inertial>
      <origin xyz="-0.00905569 -0.00297967 0.1286266" rpy="0 0 0" />
      <mass value="1.9964922" />
      <inertia ixx="0.01564069" ixy="-4.94E-05" ixz="0.00157215" iyy="0.01575071" iyz="0.000468" izz="0.00210931" />
      </inertial>
    <visual>
      <origin xyz="0 0 0" rpy="0 0 0" />
      <geometry>
        <mesh filename="meshes/R_shoulder_yaw_link.STL" />
        </geometry>
      <material name="R_shoulder_yaw_link_visual_material_15">
        <color rgba="1 1 1 1" />
        </material>
      </visual>
    <collision>
      <origin xyz="0 0 0" rpy="0 0 0" />
      <geometry>
        <mesh filename="meshes/R_shoulder_yaw_link.STL" />
        </geometry>
      </collision>
    </link>
  <link name="R_elbow_roll_link">
    <inertial>
      <origin xyz="0.00836062 -0.0579 -0.00065816" rpy="0 0 0" />
      <mass value="0.6833698" />
      <inertia ixx="0.00259975" ixy="0.00029753" ixz="-5.05E-06" iyy="0.00143259" iyz="2.64E-05" izz="0.00224873" />
      </inertial>
    <visual>
      <origin xyz="0 0 0" rpy="0 0 0" />
      <geometry>
        <mesh filename="meshes/R_elbow_roll_link.STL" />
        </geometry>
      <material name="R_elbow_roll_link_visual_material_16">
        <color rgba="1 1 1 1" />
        </material>
      </visual>
    <collision>
      <origin xyz="0 0 0" rpy="0 0 0" />
      <geometry>
        <mesh filename="meshes/R_elbow_roll_link.STL" />
        </geometry>
      </collision>
    </link>
  <link name="R_elbow_yaw_link">
    <inertial>
      <origin xyz="-0.00097407 -0.00017922 0.04577713" rpy="0 0 0" />
      <mass value="0.87457488" />
      <inertia ixx="0.00143841" ixy="3.89E-06" ixz="5.22E-05" iyy="0.00164" iyz="-7.1E-07" izz="0.00087583" />
      </inertial>
    <visual>
      <origin xyz="0 0 0" rpy="0 0 0" />
      <geometry>
        <mesh filename="meshes/R_elbow_yaw_link.STL" />
        </geometry>
      <material name="R_elbow_yaw_link_visual_material_17">
        <color rgba="1 1 1 1" />
        </material>
      </visual>
    <collision>
      <origin xyz="0 0 0" rpy="0 0 0" />
      <geometry>
        <mesh filename="meshes/R_elbow_yaw_link.STL" />
        </geometry>
      </collision>
    </link>
  <link name="R_wrist_pitch_link">
    <inertial>
      <origin xyz="-0.03844461 0.00485589 0.00477205" rpy="0 0 0" />
      <mass value="1.31445091" />
      <inertia ixx="0.00090036" ixy="0.000219" ixz="-0.00022711" iyy="0.00273144" iyz="3.05E-05" izz="0.00273579" />
      </inertial>
    <visual>
      <origin xyz="0 0 0" rpy="0 0 0" />
      <geometry>
        <mesh filename="meshes/R_wrist_pitch_link.STL" />
        </geometry>
      <material name="R_wrist_pitch_link_visual_material_18">
        <color rgba="1 1 1 1" />
        </material>
      </visual>
    <collision>
      <origin xyz="0 0 0" rpy="0 0 0" />
      <geometry>
        <mesh filename="meshes/R_wrist_pitch_link.STL" />
        </geometry>
      </collision>
    </link>
  <link name="R_wrist_roll_link">
    <inertial>
      <origin xyz="4.63E-06 0.01705624 0.0007487" rpy="0 0 0" />
      <mass value="0.15210234" />
      <inertia ixx="0.00027356" ixy="0" ixz="-2E-08" iyy="0.00021546" iyz="7.68E-06" izz="0.00011023" />
      </inertial>
    <visual>
      <origin xyz="0 0 0" rpy="0 0 0" />
      <geometry>
        <mesh filename="meshes/R_wrist_roll_link.STL" />
        </geometry>
      <material name="R_wrist_roll_link_visual_material_19">
        <color rgba="1 1 1 1" />
        </material>
      </visual>
    <collision>
      <origin xyz="0 0 0" rpy="0 0 0" />
      <geometry>
        <mesh filename="meshes/R_wrist_roll_link.STL" />
        </geometry>
      </collision>
    </link>
  <link name="R_sixforce_link">
    <inertial>
      <origin xyz="-0.00018615 -2.11E-06 -0.01106561" rpy="0 0 0" />
      <mass value="0.16999999" />
      <inertia ixx="3.57E-05" ixy="2.1E-07" ixz="7.8E-07" iyy="5.03E-05" iyz="-6E-08" izz="6.13E-05" />
      </inertial>
    <visual>
      <origin xyz="0 0 0" rpy="0 0 0" />
      <geometry>
        <mesh filename="meshes/R_sixforce_link.STL" />
        </geometry>
      <material name="R_sixforce_link_visual_material_20">
        <color rgba="1 1 1 1" />
        </material>
      </visual>
    <collision>
      <origin xyz="0 0 0" rpy="0 0 0" />
      <geometry>
        <mesh filename="meshes/R_sixforce_link.STL" />
        </geometry>
      </collision>
    </link>
  <link name="L_hip_roll_link">
    <inertial>
      <origin xyz="0.0092362 0.00068462 -0.00762458" rpy="0 0 0" />
      <mass value="1.32105747" />
      <inertia ixx="0.00186596" ixy="1.517E-05" ixz="-9.8E-05" iyy="0.00173588" iyz="2.52E-05" izz="0.00116343" />
      </inertial>
    <visual>
      <origin xyz="0 0 0" rpy="0 0 0" />
      <geometry>
        <mesh filename="meshes/L_hip_roll_link.STL" />
        </geometry>
      <material name="L_hip_roll_link_visual_material_21">
        <color rgba="1 1 1 1" />
        </material>
      </visual>
    <collision>
      <origin xyz="0 0 0" rpy="0 0 0" />
      <geometry>
        <mesh filename="meshes/L_hip_roll_link.STL" />
        </geometry>
      </collision>
    </link>
  <link name="L_hip_yaw_link">
    <inertial>
      <origin xyz="0.00023965 0.00396362 0.11568685" rpy="0 0 0" />
      <mass value="2.28909729" />
      <inertia ixx="0.00430439" ixy="3.98E-06" ixz="-9.23E-06" iyy="0.00489286" iyz="-5.1E-05" izz="0.00362774" />
      </inertial>
    <visual>
      <origin xyz="0 0 0" rpy="0 0 0" />
      <geometry>
        <mesh filename="meshes/L_hip_yaw_link.STL" />
        </geometry>
      <material name="L_hip_yaw_link_visual_material_22">
        <color rgba="1 1 1 1" />
        </material>
      </visual>
    <collision>
      <origin xyz="0 0 0" rpy="0 0 0" />
      <geometry>
        <mesh filename="meshes/L_hip_yaw_link.STL" />
        </geometry>
      </collision>
    </link>
  <link name="L_hip_pitch_link">
    <inertial>
      <origin xyz="0.0018469 -0.15590228 -0.00269388" rpy="0 0 0" />
      <mass value="4.15060522" />
      <inertia ixx="0.04292046" ixy="0.00183" ixz="6.39E-05" iyy="0.0099854" iyz="-0.00112302" izz="0.04278489" />
      </inertial>
    <visual>
      <origin xyz="0 0 0" rpy="0 0 0" />
      <geometry>
        <mesh filename="meshes/L_hip_pitch_link.STL" />
        </geometry>
      <material name="L_hip_pitch_link_visual_material_23">
        <color rgba="1 1 1 1" />
        </material>
      </visual>
    <collision>
      <origin xyz="0 0 0" rpy="0 0 0" />
      <geometry>
        <mesh filename="meshes/L_hip_pitch_link.STL" />
        </geometry>
      </collision>
    </link>
  <link name="L_knee_pitch_link">
    <inertial>
      <origin xyz="-0.00100471 -0.15954641 0.00100453" rpy="0 0 0" />
      <mass value="3.82687544" />
      <inertia ixx="0.03406888" ixy="-0.000889" ixz="-6.85E-05" iyy="0.00486479" iyz="-0.000151" izz="0.03481565" />
      </inertial>
    <visual>
      <origin xyz="0 0 0" rpy="0 0 0" />
      <geometry>
        <mesh filename="meshes/L_knee_pitch_link.STL" />
        </geometry>
      <material name="L_knee_pitch_link_visual_material_24">
        <color rgba="1 1 1 1" />
        </material>
      </visual>
    <collision>
      <origin xyz="0 0 0" rpy="0 0 0" />
      <geometry>
        <mesh filename="meshes/L_knee_pitch_link.STL" />
        </geometry>
      </collision>
    </link>
  <link name="L_ankle_pitch_link">
    <inertial>
      <origin xyz="0 0 0" rpy="0 0 0" />
      <mass value="0.06591367" />
      <inertia ixx="1.09E-05" ixy="-5E-08" ixz="0" iyy="1.84E-05" iyz="0" izz="1.09E-05" />
      </inertial>
    <visual>
      <origin xyz="0 0 0" rpy="0 0 0" />
      <geometry>
        <mesh filename="meshes/L_ankle_pitch_link.STL" />
        </geometry>
      <material name="L_ankle_pitch_link_visual_material_25">
        <color rgba="1 1 1 1" />
        </material>
      </visual>
    <collision>
      <origin xyz="0 0 0" rpy="0 0 0" />
      <geometry>
        <mesh filename="meshes/L_ankle_pitch_link.STL" />
        </geometry>
      </collision>
    </link>
  <link name="L_ankle_roll_link">
    <inertial>
      <origin xyz="-0.03099794 -0.000273 0.02397368" rpy="0 0 0" />
      <mass value="0.7830616" />
      <inertia ixx="0.00326836" ixy="-2.21E-06" ixz="0.000163" iyy="0.00288048" iyz="-7.82E-06" izz="0.00070111" />
      </inertial>
    <visual>
      <origin xyz="0 0 0" rpy="0 0 0" />
      <geometry>
        <mesh filename="meshes/L_ankle_roll_link.STL" />
        </geometry>
      <material name="L_ankle_roll_link_visual_material_26">
        <color rgba="1 1 1 1" />
        </material>
      </visual>
    <collision>
      <origin xyz="0 0 0" rpy="0 0 0" />
      <geometry>
        <mesh filename="meshes/L_ankle_roll_link.STL" />
        </geometry>
      </collision>
    </link>
  <link name="R_hip_roll_link">
    <inertial>
      <origin xyz="0.0092362 0.00068462 -0.00762458" rpy="0 0 0" />
      <mass value="1.32105747" />
      <inertia ixx="0.00186596" ixy="1.517E-05" ixz="-9.8E-05" iyy="0.00173588" iyz="2.52E-05" izz="0.00116343" />
      </inertial>
    <visual>
      <origin xyz="0 0 0" rpy="0 0 0" />
      <geometry>
        <mesh filename="meshes/R_hip_roll_link.STL" />
        </geometry>
      <material name="R_hip_roll_link_visual_material_27">
        <color rgba="1 1 1 1" />
        </material>
      </visual>
    <collision>
      <origin xyz="0 0 0" rpy="0 0 0" />
      <geometry>
        <mesh filename="meshes/R_hip_roll_link.STL" />
        </geometry>
      </collision>
    </link>
  <link name="R_hip_yaw_link">
    <inertial>
      <origin xyz="0.00023965 0.00396362 0.11568685" rpy="0 0 0" />
      <mass value="2.28909729" />
      <inertia ixx="0.00430439" ixy="3.98E-06" ixz="-9.23E-06" iyy="0.00489286" iyz="-5.1E-05" izz="0.00362774" />
      </inertial>
    <visual>
      <origin xyz="0 0 0" rpy="0 0 0" />
      <geometry>
        <mesh filename="meshes/R_hip_yaw_link.STL" />
        </geometry>
      <material name="R_hip_yaw_link_visual_material_28">
        <color rgba="1 1 1 1" />
        </material>
      </visual>
    <collision>
      <origin xyz="0 0 0" rpy="0 0 0" />
      <geometry>
        <mesh filename="meshes/R_hip_yaw_link.STL" />
        </geometry>
      </collision>
    </link>
  <link name="R_hip_pitch_link">
    <inertial>
      <origin xyz="0.00152133 -0.15560529 0.00278294" rpy="0 0 0" />
      <mass value="4.15575253" />
      <inertia ixx="0.04287391" ixy="0.00190943" ixz="-8.428E-05" iyy="0.01000225" iyz="0.00113" izz="0.04271714" />
      </inertial>
    <visual>
      <origin xyz="0 0 0" rpy="0 0 0" />
      <geometry>
        <mesh filename="meshes/R_hip_pitch_link.STL" />
        </geometry>
      <material name="R_hip_pitch_link_visual_material_29">
        <color rgba="1 1 1 1" />
        </material>
      </visual>
    <collision>
      <origin xyz="0 0 0" rpy="0 0 0" />
      <geometry>
        <mesh filename="meshes/R_hip_pitch_link.STL" />
        </geometry>
      </collision>
    </link>
  <link name="R_knee_pitch_link">
    <inertial>
      <origin xyz="-0.00100471 -0.15954641 0.00100453" rpy="0 0 0" />
      <mass value="3.82687544" />
      <inertia ixx="0.03406888" ixy="-0.000889" ixz="-6.85E-05" iyy="0.00486479" iyz="-0.000151" izz="0.03481565" />
      </inertial>
    <visual>
      <origin xyz="0 0 0" rpy="0 0 0" />
      <geometry>
        <mesh filename="meshes/R_knee_pitch_link.STL" />
        </geometry>
      <material name="R_knee_pitch_link_visual_material_30">
        <color rgba="1 1 1 1" />
        </material>
      </visual>
    <collision>
      <origin xyz="0 0 0" rpy="0 0 0" />
      <geometry>
        <mesh filename="meshes/R_knee_pitch_link.STL" />
        </geometry>
      </collision>
    </link>
  <link name="R_ankle_pitch_link">
    <inertial>
      <origin xyz="0 0 0" rpy="0 0 0" />
      <mass value="0.06591375" />
      <inertia ixx="1.09E-05" ixy="0" ixz="0" iyy="1.84E-05" iyz="0" izz="1.09E-05" />
      </inertial>
    <visual>
      <origin xyz="0 0 0" rpy="0 0 0" />
      <geometry>
        <mesh filename="meshes/R_ankle_pitch_link.STL" />
        </geometry>
      <material name="R_ankle_pitch_link_visual_material_31">
        <color rgba="1 1 1 1" />
        </material>
      </visual>
    <collision>
      <origin xyz="0 0 0" rpy="0 0 0" />
      <geometry>
        <mesh filename="meshes/R_ankle_pitch_link.STL" />
        </geometry>
      </collision>
    </link>
  <link name="R_ankle_roll_link">
    <inertial>
      <origin xyz="-0.03099814 0.00026566 0.02395108" rpy="0 0 0" />
      <mass value="0.78315603" />
      <inertia ixx="0.00326857" ixy="2.22E-06" ixz="0.000164" iyy="0.00288049" iyz="7.55E-06" izz="0.00070131" />
      </inertial>
    <visual>
      <origin xyz="0 0 0" rpy="0 0 0" />
      <geometry>
        <mesh filename="meshes/R_ankle_roll_link.STL" />
        </geometry>
      <material name="R_ankle_roll_link_visual_material_32">
        <color rgba="1 1 1 1" />
        </material>
      </visual>
    <collision>
      <origin xyz="0 0 0" rpy="0 0 0" />
      <geometry>
        <mesh filename="meshes/R_ankle_roll_link.STL" />
        </geometry>
      </collision>
    </link>
  <joint name="waist_yaw_joint" type="revolute">
    <origin xyz="-0.00092617 0 0.143" rpy="3.1416 -0.0064767 0" />
    <parent link="base_link" />
    <child link="waist_yaw_link" />
    <axis xyz="0 0 1" />
    <limit lower="-2.8274" upper="2.8274" effort="85" velocity="3.1416" />
    <dynamics damping="5.0" friction="0.05" /></joint>
  <joint name="waist_pitch_joint" type="revolute">
    <origin xyz="0 0 0" rpy="-1.5708 -0.0064767 0" />
    <parent link="waist_yaw_link" />
    <child link="waist_pitch_link" />
    <axis xyz="0 0 1" />
    <limit lower="-1.5707" upper="0.6108" effort="265" velocity="2.0944" />
    <dynamics damping="5.0" friction="0.05" /></joint>
  <joint name="head_yaw_joint" type="revolute">
    <origin xyz="0 0.4841 0" rpy="-1.5708 0 0" />
    <parent link="waist_pitch_link" />
    <child link="head_yaw_link" />
    <axis xyz="0 0 1" />
    <limit lower="-1.658" upper="1.658" effort="4.5" velocity="3.1416" />
    <dynamics damping="5.0" friction="0.05" /></joint>
  <joint name="head_pitch_joint" type="revolute">
    <origin xyz="0 0 0.025" rpy="1.5708 0 0" />
    <parent link="head_yaw_link" />
    <child link="head_pitch_link" />
    <axis xyz="0 0 1" />
    <limit lower="-0.7854" upper="0.5236" effort="4.5" velocity="3.1416" />
    <dynamics damping="5.0" friction="0.05" /></joint>
  <joint name="L_shoulder_pitch_joint" type="revolute">
    <origin xyz="-0.0046 0.34864 -0.15387" rpy="0 -0.17453 1.5708" />
    <parent link="waist_pitch_link" />
    <child link="L_shoulder_pitch_link" />
    <axis xyz="0 0 1" />
    <limit lower="-2.8623" upper="2.8623" effort="80" velocity="3.1416" />
    <dynamics damping="2.0" friction="0.02" /></joint>
  <joint name="L_shoulder_roll_joint" type="revolute">
    <origin xyz="0 0 -0.06" rpy="-1.5708 0 0" />
    <parent link="L_shoulder_pitch_link" />
    <child link="L_shoulder_roll_link" />
    <axis xyz="0 0 1" />
    <limit lower="-1.885" upper="0.1222" effort="80" velocity="3.1416" />
    <dynamics damping="2.0" friction="0.02" /></joint>
  <joint name="L_shoulder_yaw_joint" type="revolute">
    <origin xyz="-0.083 0 0" rpy="-1.5708 0 1.5708" />
    <parent link="L_shoulder_roll_link" />
    <child link="L_shoulder_yaw_link" />
    <axis xyz="0 0 1" />
    <limit lower="-2.9322" upper="2.9322" effort="45" velocity="3.1416" />
    <dynamics damping="2.0" friction="0.02" /></joint>
  <joint name="L_elbow_roll_joint" type="revolute">
    <origin xyz="-0.019993 0 0.213" rpy="-1.5708 0 0" />
    <parent link="L_shoulder_yaw_link" />
    <child link="L_elbow_roll_link" />
    <axis xyz="0 0 1" />
    <limit lower="-2.6529" upper="0.0349" effort="45" velocity="3.1416" />
    <dynamics damping="2.0" friction="0.02" /></joint>
  <joint name="L_elbow_yaw_joint" type="revolute">
    <origin xyz="0.019993 -0.10368 0" rpy="1.5708 0 0" />
    <parent link="L_elbow_roll_link" />
    <child link="L_elbow_yaw_link" />
    <axis xyz="0 0 1" />
    <limit lower="-2.9322" upper="2.9322" effort="20" velocity="3.1416" />
    <dynamics damping="2.0" friction="0.02" /></joint>
  <joint name="L_wrist_pitch_joint" type="revolute">
    <origin xyz="0 0 0.11832" rpy="3.1416 1.5708 0" />
    <parent link="L_elbow_yaw_link" />
    <child link="L_wrist_pitch_link" />
    <axis xyz="0 0 1" />
    <limit lower="-1.658" upper="1.658" effort="20" velocity="3.1416" />
    <dynamics damping="2.0" friction="0.02" /></joint>
  <joint name="L_wrist_roll_joint" type="revolute">
    <origin xyz="-0.076 0 0" rpy="1.5708 1.5708 3.1416" />
    <parent link="L_wrist_pitch_link" />
    <child link="L_wrist_roll_link" />
    <axis xyz="0 0 1" />
    <limit lower="-2.0245" upper="2.0245" effort="20" velocity="3.1416" />
    <dynamics damping="2.0" friction="0.02" /></joint>
  <joint name="L_sixforce_joint" type="fixed">
    <origin xyz="0 0.07712 0" rpy="0.0 -1.5708 -1.5708" />
    <parent link="L_wrist_roll_link" />
    <child link="L_sixforce_link" />
    <axis xyz="0 0 0" />
    </joint>
  <joint name="R_shoulder_pitch_joint" type="revolute">
    <origin xyz="-0.0046 0.34864 0.15387" rpy="3.1416 0.17453 1.5708" />
    <parent link="waist_pitch_link" />
    <child link="R_shoulder_pitch_link" />
    <axis xyz="0 0 1" />
    <limit lower="-2.8623" upper="2.8623" effort="80" velocity="3.1416" />
    <dynamics damping="2.0" friction="0.02" /></joint>
  <joint name="R_shoulder_roll_joint" type="revolute">
    <origin xyz="0 0 -0.06" rpy="-1.5708 0 0" />
    <parent link="R_shoulder_pitch_link" />
    <child link="R_shoulder_roll_link" />
    <axis xyz="0 0 1" />
    <limit lower="-1.885" upper="0.1222" effort="80" velocity="3.1416" />
    <dynamics damping="2.0" friction="0.02" /></joint>
  <joint name="R_shoulder_yaw_joint" type="revolute">
    <origin xyz="-0.083 0 0" rpy="-1.5708 -0.020023 1.5708" />
    <parent link="R_shoulder_roll_link" />
    <child link="R_shoulder_yaw_link" />
    <axis xyz="0 0 1" />
    <limit lower="-2.9322" upper="2.9322" effort="45" velocity="3.1416" />
    <dynamics damping="2.0" friction="0.02" /></joint>
  <joint name="R_elbow_roll_joint" type="revolute">
    <origin xyz="-0.019989 -0.00040028 0.213" rpy="-1.5708 0 0.020023" />
    <parent link="R_shoulder_yaw_link" />
    <child link="R_elbow_roll_link" />
    <axis xyz="0 0 1" />
    <limit lower="-2.6529" upper="0.0349" effort="45" velocity="3.1416" />
    <dynamics damping="2.0" friction="0.02" /></joint>
  <joint name="R_elbow_yaw_joint" type="revolute">
    <origin xyz="0.019993 -0.10368 0" rpy="1.5708 0 0" />
    <parent link="R_elbow_roll_link" />
    <child link="R_elbow_yaw_link" />
    <axis xyz="0 0 1" />
    <limit lower="-2.9322" upper="2.9322" effort="20" velocity="3.1416" />
    <dynamics damping="2.0" friction="0.02" /></joint>
  <joint name="R_wrist_pitch_joint" type="revolute">
    <origin xyz="0 0 0.11832" rpy="3.1416 1.5708 0" />
    <parent link="R_elbow_yaw_link" />
    <child link="R_wrist_pitch_link" />
    <axis xyz="0 0 1" />
    <limit lower="-1.658" upper="1.658" effort="20" velocity="3.1416" />
    <dynamics damping="2.0" friction="0.02" /></joint>
  <joint name="R_wrist_roll_joint" type="revolute">
    <origin xyz="-0.076 0 0" rpy="1.5708 1.5708 3.1416" />
    <parent link="R_wrist_pitch_link" />
    <child link="R_wrist_roll_link" />
    <axis xyz="0 0 1" />
    <limit lower="-2.0245" upper="2.0245" effort="20" velocity="3.1416" />
    <dynamics damping="2.0" friction="0.02" /></joint>
  <joint name="R_sixforce_joint" type="fixed">
    <origin xyz="0 0.07712 0" rpy="-1.5708 1.5708 0" />
    <parent link="R_wrist_roll_link" />
    <child link="R_sixforce_link" />
    <axis xyz="0 0 0" />
    </joint>
  <joint name="L_hip_roll_joint" type="revolute">
    <origin xyz="0 0.105 0" rpy="0 1.5643 0" />
    <parent link="base_link" />
    <child link="L_hip_roll_link" />
    <axis xyz="0 0 1" />
    <limit lower="-0.4363" upper="0.7853" effort="225" velocity="3.1416" />
    <dynamics damping="2.0" friction="0.02" /></joint>
  <joint name="L_hip_yaw_joint" type="revolute">
    <origin xyz="0 0 0" rpy="1.8488 -1.5708 1.2928" />
    <parent link="L_hip_roll_link" />
    <child link="L_hip_yaw_link" />
    <axis xyz="0 0 1" />
    <limit lower="-0.7853" upper="1.0471" effort="65" velocity="5.236" />
    <dynamics damping="2.0" friction="0.02" /></joint>
  <joint name="L_hip_pitch_joint" type="revolute">
    <origin xyz="0 0 0.122" rpy="-1.5708 0 0" />
    <parent link="L_hip_yaw_link" />
    <child link="L_hip_pitch_link" />
    <axis xyz="0 0 1" />
    <limit lower="-0.349" upper="1.9198" effort="225" velocity="8.7266" />
    <dynamics damping="2.0" friction="0.02" /></joint>
  <joint name="L_knee_pitch_joint" type="revolute">
    <origin xyz="0 -0.36 0" rpy="0 0 0" />
    <parent link="L_hip_pitch_link" />
    <child link="L_knee_pitch_link" />
    <axis xyz="0 0 1" />
    <limit lower="-2.2689" upper="0.0872" effort="225" velocity="9.5993" />
    <dynamics damping="2.0" friction="0.02" /></joint>
  <joint name="L_ankle_pitch_joint" type="revolute">
    <origin xyz="0 -0.37 0" rpy="0 0 -0.0064767" />
    <parent link="L_knee_pitch_link" />
    <child link="L_ankle_pitch_link" />
    <axis xyz="0 0 1" />
    <limit lower="-0.5235" upper="1.0471" effort="65" velocity="8.7266" />
    <dynamics damping="2.0" friction="0.02" /></joint>
  <joint name="L_ankle_roll_joint" type="revolute">
    <origin xyz="0 0 0" rpy="1.5708 0 1.5773" />
    <parent link="L_ankle_pitch_link" />
    <child link="L_ankle_roll_link" />
    <axis xyz="0 0 1" />
    <limit lower="-0.5235" upper="0.5235" effort="65" velocity="8.7266" />
    <dynamics damping="2.0" friction="0.02" /></joint>
  <joint name="R_hip_roll_joint" type="revolute">
    <origin xyz="0 -0.105 0" rpy="0 1.5643 0" />
    <parent link="base_link" />
    <child link="R_hip_roll_link" />
    <axis xyz="0 0 1" />
    <limit lower="-0.7853" upper="0.4363" effort="225" velocity="3.1416" />
    <dynamics damping="2.0" friction="0.02" /></joint>
  <joint name="R_hip_yaw_joint" type="revolute">
    <origin xyz="0 0 0" rpy="1.6249 -1.5708 1.5167" />
    <parent link="R_hip_roll_link" />
    <child link="R_hip_yaw_link" />
    <axis xyz="0 0 1" />
    <limit lower="-1.0471" upper="0.7853" effort="65" velocity="5.236" />
    <dynamics damping="2.0" friction="0.02" /></joint>
  <joint name="R_hip_pitch_joint" type="revolute">
    <origin xyz="0 0 0.122" rpy="-1.5708 0 0" />
    <parent link="R_hip_yaw_link" />
    <child link="R_hip_pitch_link" />
    <axis xyz="0 0 1" />
    <limit lower="-0.349" upper="1.9198" effort="225" velocity="8.7266" />
    <dynamics damping="2.0" friction="0.02" /></joint>
  <joint name="R_knee_pitch_joint" type="revolute">
    <origin xyz="0 -0.36 0" rpy="0 0 0" />
    <parent link="R_hip_pitch_link" />
    <child link="R_knee_pitch_link" />
    <axis xyz="0 0 1" />
    <limit lower="-2.2689" upper="0.0872" effort="225" velocity="9.5993" />
    <dynamics damping="2.0" friction="0.02" /></joint>
  <joint name="R_ankle_pitch_joint" type="revolute">
    <origin xyz="0 -0.37 0" rpy="0 0 0" />
    <parent link="R_knee_pitch_link" />
    <child link="R_ankle_pitch_link" />
    <axis xyz="0 0 1" />
    <limit lower="-0.5235" upper="1.0471" effort="65" velocity="8.7266" />
    <dynamics damping="2.0" friction="0.02" /></joint>
  <joint name="R_ankle_roll_joint" type="revolute">
    <origin xyz="0 0 0" rpy="1.5708 0 1.5708" />
    <parent link="R_ankle_pitch_link" />
    <child link="R_ankle_roll_link" />
    <axis xyz="0 0 1" />
    <limit lower="-0.5235" upper="0.5235" effort="65" velocity="8.7266" />
    <dynamics damping="2.0" friction="0.02" /></joint>
  <joint name="L_wrist_to_hand_base_joint" type="fixed">
    <origin xyz="0 0 0" rpy="0 0 0" />
    <parent link="L_sixforce_link" />
    <child link="L_hand_base_link" />
    </joint>
  <joint name="R_wrist_to_hand_base_joint" type="fixed">
    <origin xyz="0 0 0" rpy="0 0 3.1415927" />
    <parent link="R_sixforce_link" />
    <child link="R_hand_base_link" />
    </joint>
  <link name="L_hand_base_link">
    <inertial>
      <origin xyz="0.00065934 0.00064662 0.02223161" rpy="0 0 0" />
      <mass value="0.05238695" />
      <inertia ixx="0.00001722" ixy="0.00000028" ixz="-0.00000043" iyy="0.00003682" iyz="-0.00000022" izz="0.00004011" />
      </inertial>
    <visual>
      <origin xyz="0 0 0" rpy="0 0 0" />
      <geometry>
        <mesh filename="meshes/L_hand_base_link.STL" />
        </geometry>
      <material name="L_hand_base_link_visual_material_33">
        <color rgba="0.792156862745098 0.819607843137255 0.933333333333333 1" />
        </material>
      </visual>
    </link>
  <link name="L_palm_link">
    <inertial>
      <origin xyz="-0.00938866 -0.00221701 -0.0117814" rpy="0 0 0" />
      <mass value="0.38223591" />
      <inertia ixx="0.00022773" ixy="-0.00000169" ixz="0.00000005" iyy="0.00035269" iyz="-0.00001316" izz="0.00050349" />
      </inertial>
    <visual>
      <origin xyz="0 0 0" rpy="0 0 0" />
      <geometry>
        <mesh filename="meshes/L_palm_link.STL" />
        </geometry>
      <material name="L_palm_link_visual_material_34">
        <color rgba="1 1 1 1" />
        </material>
      </visual>
    </link>
  <link name="L_thumb_cmp_link">
    <inertial>
      <origin xyz="0.00563085 -0.00075 -0.00435852" rpy="0 0 0" />
      <mass value="0.01511033" />
      <inertia ixx="0.00000093" ixy="0.00000007" ixz="0.0000003" iyy="0.00000105" iyz="-0.00000002" izz="0.00000107" />
      </inertial>
    <visual>
      <origin xyz="0 0 0" rpy="0 0 0" />
      <geometry>
        <mesh filename="meshes/L_thumb_cmp_link.STL" />
        </geometry>
      <material name="L_thumb_cmp_link_visual_material_35">
        <color rgba="0.752941176470588 0.752941176470588 0.752941176470588 1" />
        </material>
      </visual>
    <collision name="simplified_box">
      <origin xyz="0.0018500 -0.0010557 -0.0068472" rpy="0.0000000 -0.0000000 0.0000000" />
      <geometry>
        <box size="0.0226100 0.0175212 0.0150763" />
        </geometry>
      </collision>
    </link>
  <link name="L_thumb_mpp_link">
    <inertial>
      <origin xyz="0.03618423 -0.00195018 -0.00007704" rpy="0 0 0" />
      <mass value="0.06741198" />
      <inertia ixx="0.00000637" ixy="-0.00000267" ixz="0.00000003" iyy="0.00003296" iyz="0" izz="0.00003268" />
      </inertial>
    <visual>
      <origin xyz="0 0 0" rpy="0 0 0" />
      <geometry>
        <mesh filename="meshes/L_thumb_mpp_link.STL" />
        </geometry>
      <material name="L_thumb_mpp_link_visual_material_36">
        <color rgba="0.752941176470588 0.752941176470588 0.752941176470588 1" />
        </material>
      </visual>
    <collision name="simplified_capsule_body">
      <origin xyz="0.0361574 -0.0053773 0.0004644" rpy="1.6163308 1.5031072 -1.5227726" />
      <geometry>
        <cylinder radius="0.0088918" length="0.0576820" />
        </geometry>
      </collision>
    <collision name="simplified_capsule_a">
      <origin xyz="0.0649981 -0.0053025 0.0005532" rpy="0.0000000 -0.0000000 0.0000000" />
      <geometry>
        <sphere radius="0.0088918" />
        </geometry>
      </collision>
    <collision name="simplified_capsule_b">
      <origin xyz="0.0073166 -0.0054521 0.0003756" rpy="0.0000000 -0.0000000 0.0000000" />
      <geometry>
        <sphere radius="0.0088918" />
        </geometry>
      </collision>
    </link>
  <link name="L_thumb_ip_link">
    <inertial>
      <origin xyz="0.01353705 0.00416931 0.00000614" rpy="0 0 0" />
      <mass value="0.01731117" />
      <inertia ixx="0.00000104" ixy="-0.00000015" ixz="0" iyy="0.00000185" iyz="0" izz="0.00000176" />
      </inertial>
    <visual>
      <origin xyz="0 0 0" rpy="0 0 0" />
      <geometry>
        <mesh filename="meshes/L_thumb_ip_link.STL" />
        </geometry>
      <material name="L_thumb_ip_link_visual_material_37">
        <color rgba="0.752941176470588 0.752941176470588 0.752941176470588 1" />
        </material>
      </visual>
    <collision name="simplified_capsule_body">
      <origin xyz="0.0113617 -0.0051266 0.0001749" rpy="2.6962664 -1.5598542 -2.6457149" />
      <geometry>
        <cylinder radius="0.0074832" length="0.0174154" />
        </geometry>
      </collision>
    <collision name="simplified_capsule_a">
      <origin xyz="0.0200579 -0.0046868 0.0002609" rpy="0.0000000 -0.0000000 0.0000000" />
      <geometry>
        <sphere radius="0.0074832" />
        </geometry>
      </collision>
    <collision name="simplified_capsule_b">
      <origin xyz="0.0026655 -0.0055663 0.0000889" rpy="0.0000000 -0.0000000 0.0000000" />
      <geometry>
        <sphere radius="0.0074832" />
        </geometry>
      </collision>
    </link>
  <link name="L_index_mpp_link">
    <inertial>
      <origin xyz="0.01525314 -0.00181681 0.00015205" rpy="0 0 0" />
      <mass value="0.01470075" />
      <inertia ixx="0.00000087" ixy="0" ixz="0" iyy="0.00000357" iyz="0" izz="0.00000352" />
      </inertial>
    <visual>
      <origin xyz="0 0 0" rpy="0 0 0" />
      <geometry>
        <mesh filename="meshes/L_index_mpp_link.STL" />
        </geometry>
      <material name="L_index_mpp_link_visual_material_38">
        <color rgba="0.752941176470588 0.752941176470588 0.752941176470588 1" />
        </material>
      </visual>
    <collision name="simplified_capsule_body">
      <origin xyz="0.0118700 -0.0002617 -0.0000013" rpy="-1.6212945 -1.1306932 1.7391749" />
      <geometry>
        <cylinder radius="0.0080866" length="0.0378471" />
        </geometry>
      </collision>
    <collision name="simplified_capsule_a">
      <origin xyz="0.0306469 0.0020536 0.0004056" rpy="0.0000000 -0.0000000 0.0000000" />
      <geometry>
        <sphere radius="0.0080866" />
        </geometry>
      </collision>
    <collision name="simplified_capsule_b">
      <origin xyz="-0.0069070 -0.0025770 -0.0004083" rpy="0.0000000 -0.0000000 0.0000000" />
      <geometry>
        <sphere radius="0.0080866" />
        </geometry>
      </collision>
    </link>
  <link name="L_index_ip_link">
    <inertial>
      <origin xyz="0.01680857 -0.00117535 0" rpy="0 0 0" />
      <mass value="0.01334933" />
      <inertia ixx="0.00000042" ixy="-0.00000029" ixz="0" iyy="0.00000262" iyz="0" izz="0.00000261" />
      </inertial>
    <visual>
      <origin xyz="0 0 0" rpy="0 0 0" />
      <geometry>
        <mesh filename="meshes/L_index_ip_link.STL" />
        </geometry>
      <material name="L_index_ip_link_visual_material_39">
        <color rgba="0.752941176470588 0.752941176470588 0.752941176470588 1" />
        </material>
      </visual>
    <collision name="simplified_capsule_body">
      <origin xyz="0.0174116 -0.0000422 -0.0000141" rpy="-1.5631654 -1.5626493 1.7554213" />
      <geometry>
        <cylinder radius="0.0050949" length="0.0356763" />
        </geometry>
      </collision>
    <collision name="simplified_capsule_a">
      <origin xyz="0.0349211 0.0033662 -0.0000152" rpy="0.0000000 -0.0000000 0.0000000" />
      <geometry>
        <sphere radius="0.0050949" />
        </geometry>
      </collision>
    <collision name="simplified_capsule_b">
      <origin xyz="-0.0000979 -0.0034506 -0.0000130" rpy="0.0000000 -0.0000000 0.0000000" />
      <geometry>
        <sphere radius="0.0050949" />
        </geometry>
      </collision>
    </link>
  <link name="L_middle_mpp_link">
    <inertial>
      <origin xyz="0.01476009 -0.00171481 0.00012869" rpy="0 0 0" />
      <mass value="0.01430214" />
      <inertia ixx="0.00000086" ixy="-0.00000003" ixz="0" iyy="0.00000344" iyz="0" izz="0.00000339" />
      </inertial>
    <visual>
      <origin xyz="0 0 0" rpy="0 0 0" />
      <geometry>
        <mesh filename="meshes/L_middle_mpp_link.STL" />
        </geometry>
      <material name="L_middle_mpp_link_visual_material_40">
        <color rgba="0.752941176470588 0.752941176470588 0.752941176470588 1" />
        </material>
      </visual>
    <collision name="simplified_capsule_body">
      <origin xyz="0.0118700 -0.0002617 -0.0000013" rpy="-1.6212945 -1.1306932 1.7391749" />
      <geometry>
        <cylinder radius="0.0080866" length="0.0378471" />
        </geometry>
      </collision>
    <collision name="simplified_capsule_a">
      <origin xyz="0.0306469 0.0020536 0.0004056" rpy="0.0000000 -0.0000000 0.0000000" />
      <geometry>
        <sphere radius="0.0080866" />
        </geometry>
      </collision>
    <collision name="simplified_capsule_b">
      <origin xyz="-0.0069070 -0.0025770 -0.0004083" rpy="0.0000000 -0.0000000 0.0000000" />
      <geometry>
        <sphere radius="0.0080866" />
        </geometry>
      </collision>
    </link>
  <link name="L_middle_ip_link">
    <inertial>
      <origin xyz="0.01771317 -0.00109666 0.0000256" rpy="0 0 0" />
      <mass value="0.0148881" />
      <inertia ixx="0.00000047" ixy="-0.00000038" ixz="0" iyy="0.00000344" iyz="0" izz="0.00000344" />
      </inertial>
    <visual>
      <origin xyz="0 0 0" rpy="0 0 0" />
      <geometry>
        <mesh filename="meshes/L_middle_ip_link.STL" />
        </geometry>
      <material name="L_middle_ip_link_visual_material_41">
        <color rgba="0.752941176470588 0.752941176470588 0.752941176470588 1" />
        </material>
      </visual>
    <collision name="simplified_capsule_body">
      <origin xyz="0.0189061 0.0003019 0.0000804" rpy="1.5804671 -1.5372421 -1.3937254" />
      <geometry>
        <cylinder radius="0.0053218" length="0.0378533" />
        </geometry>
      </collision>
    <collision name="simplified_capsule_a">
      <origin xyz="0.0375037 0.0038157 0.0000866" rpy="0.0000000 -0.0000000 0.0000000" />
      <geometry>
        <sphere radius="0.0053218" />
        </geometry>
      </collision>
    <collision name="simplified_capsule_b">
      <origin xyz="0.0003085 -0.0032119 0.0000743" rpy="0.0000000 -0.0000000 0.0000000" />
      <geometry>
        <sphere radius="0.0053218" />
        </geometry>
      </collision>
    </link>
  <link name="L_ring_mpp_link">
    <inertial>
      <origin xyz="0.01475954 -0.00171495 0.00012869" rpy="0 0 0" />
      <mass value="0.01430214" />
      <inertia ixx="0.00000086" ixy="-0.00000003" ixz="0" iyy="0.00000344" iyz="0" izz="0.00000339" />
      </inertial>
    <visual>
      <origin xyz="0 0 0" rpy="0 0 0" />
      <geometry>
        <mesh filename="meshes/L_ring_mpp_link.STL" />
        </geometry>
      <material name="L_ring_mpp_link_visual_material_42">
        <color rgba="0.752941176470588 0.752941176470588 0.752941176470588 1" />
        </material>
      </visual>
    <collision name="simplified_capsule_body">
      <origin xyz="0.0118700 -0.0002617 -0.0000013" rpy="-1.6212945 -1.1306932 1.7391749" />
      <geometry>
        <cylinder radius="0.0080866" length="0.0378471" />
        </geometry>
      </collision>
    <collision name="simplified_capsule_a">
      <origin xyz="0.0306469 0.0020536 0.0004056" rpy="0.0000000 -0.0000000 0.0000000" />
      <geometry>
        <sphere radius="0.0080866" />
        </geometry>
      </collision>
    <collision name="simplified_capsule_b">
      <origin xyz="-0.0069070 -0.0025770 -0.0004083" rpy="0.0000000 -0.0000000 0.0000000" />
      <geometry>
        <sphere radius="0.0080866" />
        </geometry>
      </collision>
    </link>
  <link name="L_ring_ip_link">
    <inertial>
      <origin xyz="0.01615432 -0.00130235 0.00002763" rpy="0 0 0" />
      <mass value="0.01374794" />
      <inertia ixx="0.00000043" ixy="-0.00000033" ixz="0" iyy="0.00000282" iyz="0" izz="0.00000281" />
      </inertial>
    <visual>
      <origin xyz="0 0 0" rpy="0 0 0" />
      <geometry>
        <mesh filename="meshes/L_ring_ip_link.STL" />
        </geometry>
      <material name="L_ring_ip_link_visual_material_43">
        <color rgba="0.752941176470588 0.752941176470588 0.752941176470588 1" />
        </material>
      </visual>
    <collision name="simplified_capsule_body">
      <origin xyz="0.0174116 -0.0000422 -0.0000141" rpy="-1.5631654 -1.5626493 1.7554213" />
      <geometry>
        <cylinder radius="0.0050949" length="0.0356763" />
        </geometry>
      </collision>
    <collision name="simplified_capsule_a">
      <origin xyz="0.0349211 0.0033662 -0.0000152" rpy="0.0000000 -0.0000000 0.0000000" />
      <geometry>
        <sphere radius="0.0050949" />
        </geometry>
      </collision>
    <collision name="simplified_capsule_b">
      <origin xyz="-0.0000979 -0.0034506 -0.0000130" rpy="0.0000000 -0.0000000 0.0000000" />
      <geometry>
        <sphere radius="0.0050949" />
        </geometry>
      </collision>
    </link>
  <link name="L_little_mpp_link">
    <inertial>
      <origin xyz="0.0147588 -0.00171514 0.00012869" rpy="0 0 0" />
      <mass value="0.01430214" />
      <inertia ixx="0.00000086" ixy="-0.00000003" ixz="0" iyy="0.00000344" iyz="0" izz="0.00000339" />
      </inertial>
    <visual>
      <origin xyz="0 0 0" rpy="0 0 0" />
      <geometry>
        <mesh filename="meshes/L_little_mpp_link.STL" />
        </geometry>
      <material name="L_little_mpp_link_visual_material_44">
        <color rgba="0.752941176470588 0.752941176470588 0.752941176470588 1" />
        </material>
      </visual>
    <collision name="simplified_capsule_body">
      <origin xyz="0.0118700 -0.0002617 -0.0000013" rpy="-1.6212945 -1.1306932 1.7391749" />
      <geometry>
        <cylinder radius="0.0080866" length="0.0378471" />
        </geometry>
      </collision>
    <collision name="simplified_capsule_a">
      <origin xyz="0.0306469 0.0020536 0.0004056" rpy="0.0000000 -0.0000000 0.0000000" />
      <geometry>
        <sphere radius="0.0080866" />
        </geometry>
      </collision>
    <collision name="simplified_capsule_b">
      <origin xyz="-0.0069070 -0.0025770 -0.0004083" rpy="0.0000000 -0.0000000 0.0000000" />
      <geometry>
        <sphere radius="0.0080866" />
        </geometry>
      </collision>
    </link>
  <link name="L_little_ip_link">
    <inertial>
      <origin xyz="0.01303327 -0.00143438 0.0000295" rpy="0 0 0" />
      <mass value="0.01179268" />
      <inertia ixx="0.00000034" ixy="-0.00000023" ixz="0" iyy="0.00000179" iyz="0" izz="0.00000178" />
      </inertial>
    <visual>
      <origin xyz="0 0 0" rpy="0 0 0" />
      <geometry>
        <mesh filename="meshes/L_little_ip_link.STL" />
        </geometry>
      <material name="L_little_ip_link_visual_material_45">
        <color rgba="0.752941176470588 0.752941176470588 0.752941176470588 1" />
        </material>
      </visual>
    <collision name="simplified_capsule_body">
      <origin xyz="0.0135435 -0.0005172 0.0000112" rpy="-1.6408258 -1.3509387 1.8653817" />
      <geometry>
        <cylinder radius="0.0049832" length="0.0293788" />
        </geometry>
      </collision>
    <collision name="simplified_capsule_a">
      <origin xyz="0.0278569 0.0027775 0.0002354" rpy="0.0000000 -0.0000000 0.0000000" />
      <geometry>
        <sphere radius="0.0049832" />
        </geometry>
      </collision>
    <collision name="simplified_capsule_b">
      <origin xyz="-0.0007700 -0.0038118 -0.0002129" rpy="0.0000000 -0.0000000 0.0000000" />
      <geometry>
        <sphere radius="0.0049832" />
        </geometry>
      </collision>
    </link>
  <joint name="L_palm_joint" type="fixed">
    <origin xyz="0.00035572 -0.013196 0.099778" rpy="1.5708 -1.5708 0" />
    <parent link="L_hand_base_link" />
    <child link="L_palm_link" />
    <axis xyz="0 0 0" />
    <limit lower="0" upper="0" effort="0" velocity="0" />
    </joint>
  <joint name="L_thumb_cmp_joint" type="revolute">
    <origin xyz="-0.048578 0.028956 -0.0073648" rpy="-1.5708 -0.75224 1.5708" />
    <parent link="L_palm_link" />
    <child link="L_thumb_cmp_link" />
    <axis xyz="0 0 1" />
    <limit lower="-0.96" upper="0" effort="1.35" velocity="2.09" />
    <dynamics damping="2.0" friction="0.02" /></joint>
  <joint name="L_thumb_mpp_joint" type="revolute">
    <origin xyz="0.012 -0.0010557 -0.010045" rpy="-1.6755 0 0" />
    <parent link="L_thumb_cmp_link" />
    <child link="L_thumb_mpp_link" />
    <axis xyz="0 0 1" />
    <limit lower="0" upper="1.04" effort="1.35" velocity="2.09" />
    <dynamics damping="2.0" friction="0.02" /></joint>
  <joint name="L_thumb_ip_joint" type="revolute">
    <origin xyz="0.075 -1.163E-05 0" rpy="0 0 0" />
    <parent link="L_thumb_mpp_link" />
    <child link="L_thumb_ip_link" />
    <axis xyz="0 0 1" />
    <limit lower="0" upper="1.05" effort="1.35" velocity="2.09" />
    <dynamics damping="2.0" friction="0.02" /></joint>
  <joint name="L_index_mpp_joint" type="revolute">
    <origin xyz="0.041817 0.030769 -0.011696" rpy="1.5708 -0.18118 0.020071" />
    <parent link="L_palm_link" />
    <child link="L_index_mpp_link" />
    <axis xyz="0 0 1" />
    <limit lower="0" upper="1.46" effort="1.35" velocity="2.09" />
    <dynamics damping="2.0" friction="0.02" /></joint>
  <joint name="L_index_ip_joint" type="revolute">
    <origin xyz="0.0388 0 0" rpy="0 0 -0.014509" />
    <parent link="L_index_mpp_link" />
    <child link="L_index_ip_link" />
    <axis xyz="0 0 1" />
    <limit lower="0" upper="1.62" effort="1.35" velocity="2.09" />
    <dynamics damping="2.0" friction="0.02" /></joint>
  <joint name="L_middle_mpp_joint" type="revolute">
    <origin xyz="0.042022 0.010356 -0.011696" rpy="1.5708 -0.18118 0" />
    <parent link="L_palm_link" />
    <child link="L_middle_mpp_link" />
    <axis xyz="0 0 1" />
    <limit lower="0" upper="1.46" effort="1.35" velocity="2.09" />
    <dynamics damping="2.0" friction="0.02" /></joint>
  <joint name="L_middle_ip_joint" type="revolute">
    <origin xyz="0.0388 0 0" rpy="0 0 -0.012066" />
    <parent link="L_middle_mpp_link" />
    <child link="L_middle_ip_link" />
    <axis xyz="0 0 1" />
    <limit lower="0" upper="1.62" effort="1.35" velocity="2.09" />
    <dynamics damping="2.0" friction="0.02" /></joint>
  <joint name="L_ring_mpp_joint" type="revolute">
    <origin xyz="0.041817 -0.010057 -0.011696" rpy="1.5708 -0.18118 -0.020071" />
    <parent link="L_palm_link" />
    <child link="L_ring_mpp_link" />
    <axis xyz="0 0 1" />
    <limit lower="0" upper="1.46" effort="1.35" velocity="2.09" />
    <dynamics damping="2.0" friction="0.02" /></joint>
  <joint name="L_ring_ip_joint" type="revolute">
    <origin xyz="0.0388 0 0" rpy="0 0 -0.014509" />
    <parent link="L_ring_mpp_link" />
    <child link="L_ring_ip_link" />
    <axis xyz="0 0 1" />
    <limit lower="0" upper="1.62" effort="1.35" velocity="2.09" />
    <dynamics damping="2.0" friction="0.02" /></joint>
  <joint name="L_little_mpp_joint" type="revolute">
    <origin xyz="0.041203 -0.030462 -0.011696" rpy="1.5708 -0.18118 -0.040143" />
    <parent link="L_palm_link" />
    <child link="L_little_mpp_link" />
    <axis xyz="0 0 1" />
    <limit lower="0" upper="1.46" effort="1.35" velocity="2.09" />
    <dynamics damping="2.0" friction="0.02" /></joint>
  <joint name="L_little_ip_joint" type="revolute">
    <origin xyz="0.0388 0 0" rpy="0 0 -0.014509" />
    <parent link="L_little_mpp_link" />
    <child link="L_little_ip_link" />
    <axis xyz="0 0 1" />
    <limit lower="0" upper="1.62" effort="1.35" velocity="2.09" />
    <dynamics damping="2.0" friction="0.02" /></joint>
  <link name="R_hand_base_link">
    <inertial>
      <origin xyz="0.00065934 -0.00064662 0.02223161" rpy="0 0 0" />
      <mass value="0.05238695" />
      <inertia ixx="0.00001722" ixy="-0.00000028" ixz="-0.00000043" iyy="0.00003682" iyz="0.00000022" izz="0.00004011" />
      </inertial>
    <visual>
      <origin xyz="0 0 0" rpy="0 0 0" />
      <geometry>
        <mesh filename="meshes/R_hand_base_link.STL" />
        </geometry>
      <material name="R_hand_base_link_visual_material_46">
        <color rgba="0.792156862745098 0.819607843137255 0.933333333333333 1" />
        </material>
      </visual>
    </link>
  <link name="R_palm_link">
    <inertial>
      <origin xyz="-0.00938866 0.00221701 -0.0117814" rpy="0 0 0" />
      <mass value="0.38223591" />
      <inertia ixx="0.00022773" ixy="0.00000169" ixz="0.00000005" iyy="0.00035269" iyz="0.00001316" izz="0.00050349" />
      </inertial>
    <visual>
      <origin xyz="0 0 0" rpy="0 0 0" />
      <geometry>
        <mesh filename="meshes/R_palm_link.STL" />
        </geometry>
      <material name="R_palm_link_visual_material_47">
        <color rgba="0.752941176470588 0.752941176470588 0.752941176470588 1" />
        </material>
      </visual>
    </link>
  <link name="R_thumb_cmp_link">
    <inertial>
      <origin xyz="0.00563085 0.00075 -0.00435852" rpy="0 0 0" />
      <mass value="0.01511033" />
      <inertia ixx="0.00000093" ixy="-0.00000007" ixz="0.0000003" iyy="0.00000105" iyz="0.00000002" izz="0.00000107" />
      </inertial>
    <visual>
      <origin xyz="0 0 0" rpy="0 0 0" />
      <geometry>
        <mesh filename="meshes/R_thumb_cmp_link.STL" />
        </geometry>
      <material name="R_thumb_cmp_link_visual_material_48">
        <color rgba="0.752941176470588 0.752941176470588 0.752941176470588 1" />
        </material>
      </visual>
    <collision name="simplified_box">
      <origin xyz="0.0018500 0.0010557 -0.0068472" rpy="0.0000000 -0.0000000 0.0000000" />
      <geometry>
        <box size="0.0226100 0.0175212 0.0150763" />
        </geometry>
      </collision>
    </link>
  <link name="R_thumb_mpp_link">
    <inertial>
      <origin xyz="0.03618423 -0.00195018 0.00007704" rpy="0 0 0" />
      <mass value="0.06741198" />
      <inertia ixx="0.00000637" ixy="-0.00000267" ixz="-0.00000003" iyy="0.00003296" iyz="0" izz="0.00003268" />
      </inertial>
    <visual>
      <origin xyz="0 0 0" rpy="0 0 0" />
      <geometry>
        <mesh filename="meshes/R_thumb_mpp_link.STL" />
        </geometry>
      <material name="R_thumb_mpp_link_visual_material_49">
        <color rgba="0.752941176470588 0.752941176470588 0.752941176470588 1" />
        </material>
      </visual>
    <collision name="simplified_capsule_body">
      <origin xyz="0.0361543 -0.0053741 -0.0004652" rpy="1.5268045 -1.5022961 -1.5246188" />
      <geometry>
        <cylinder radius="0.0088946" length="0.0576672" />
        </geometry>
      </collision>
    <collision name="simplified_capsule_a">
      <origin xyz="0.0649877 -0.0053081 -0.0005520" rpy="0.0000000 -0.0000000 0.0000000" />
      <geometry>
        <sphere radius="0.0088946" />
        </geometry>
      </collision>
    <collision name="simplified_capsule_b">
      <origin xyz="0.0073209 -0.0054401 -0.0003784" rpy="0.0000000 -0.0000000 0.0000000" />
      <geometry>
        <sphere radius="0.0088946" />
        </geometry>
      </collision>
    </link>
  <link name="R_thumb_ip_link">
    <inertial>
      <origin xyz="0.01353705 0.00416931 -0.00000614" rpy="0 0 0" />
      <mass value="0.01731117" />
      <inertia ixx="0.00000104" ixy="-0.00000015" ixz="0" iyy="0.00000185" iyz="0" izz="0.00000176" />
      </inertial>
    <visual>
      <origin xyz="0 0 0" rpy="0 0 0" />
      <geometry>
        <mesh filename="meshes/R_thumb_ip_link.STL" />
        </geometry>
      <material name="R_thumb_ip_link_visual_material_50">
        <color rgba="0.752941176470588 0.752941176470588 0.752941176470588 1" />
        </material>
      </visual>
    <collision name="simplified_capsule_body">
      <origin xyz="0.0112924 -0.0052491 -0.0001525" rpy="0.1012037 -1.5614730 -0.0614675" />
      <geometry>
        <cylinder radius="0.0074774" length="0.0174367" />
        </geometry>
      </collision>
    <collision name="simplified_capsule_a">
      <origin xyz="0.0200035 -0.0049027 -0.0002334" rpy="0.0000000 -0.0000000 0.0000000" />
      <geometry>
        <sphere radius="0.0074774" />
        </geometry>
      </collision>
    <collision name="simplified_capsule_b">
      <origin xyz="0.0025813 -0.0055954 -0.0000716" rpy="0.0000000 -0.0000000 0.0000000" />
      <geometry>
        <sphere radius="0.0074774" />
        </geometry>
      </collision>
    </link>
  <link name="R_index_mpp_link">
    <inertial>
      <origin xyz="0.01525314 -0.00181681 -0.00015205" rpy="0 0 0" />
      <mass value="0.01470075" />
      <inertia ixx="0.00000087" ixy="0" ixz="0" iyy="0.00000357" iyz="0" izz="0.00000352" />
      </inertial>
    <visual>
      <origin xyz="0 0 0" rpy="0 0 0" />
      <geometry>
        <mesh filename="meshes/R_index_mpp_link.STL" />
        </geometry>
      <material name="R_index_mpp_link_visual_material_51">
        <color rgba="0.752941176470588 0.752941176470588 0.752941176470588 1" />
        </material>
      </visual>
    <collision name="simplified_capsule_body">
      <origin xyz="0.0118697 -0.0002624 0.0000016" rpy="1.5198306 -1.1316436 -1.4017567" />
      <geometry>
        <cylinder radius="0.0080883" length="0.0378450" />
        </geometry>
      </collision>
    <collision name="simplified_capsule_a">
      <origin xyz="0.0306450 0.0020568 -0.0004082" rpy="0.0000000 -0.0000000 0.0000000" />
      <geometry>
        <sphere radius="0.0080883" />
        </geometry>
      </collision>
    <collision name="simplified_capsule_b">
      <origin xyz="-0.0069056 -0.0025816 0.0004115" rpy="0.0000000 -0.0000000 0.0000000" />
      <geometry>
        <sphere radius="0.0080883" />
        </geometry>
      </collision>
    </link>
  <link name="R_index_ip_link">
    <inertial>
      <origin xyz="0.01680857 -0.00117535 0" rpy="0 0 0" />
      <mass value="0.01334933" />
      <inertia ixx="0.00000042" ixy="-0.00000029" ixz="0" iyy="0.00000262" iyz="0" izz="0.00000261" />
      </inertial>
    <visual>
      <origin xyz="0 0 0" rpy="0 0 0" />
      <geometry>
        <mesh filename="meshes/R_index_ip_link.STL" />
        </geometry>
      <material name="R_index_ip_link_visual_material_52">
        <color rgba="0.752941176470588 0.752941176470588 0.752941176470588 1" />
        </material>
      </visual>
    <collision name="simplified_capsule_body">
      <origin xyz="0.0174140 -0.0000459 -0.0000026" rpy="-1.7203435 -1.5702529 1.9115170" />
      <geometry>
        <cylinder radius="0.0050913" length="0.0356850" />
        </geometry>
      </collision>
    <collision name="simplified_capsule_a">
      <origin xyz="0.0349315 0.0033443 -0.0000011" rpy="0.0000000 -0.0000000 0.0000000" />
      <geometry>
        <sphere radius="0.0050913" />
        </geometry>
      </collision>
    <collision name="simplified_capsule_b">
      <origin xyz="-0.0001034 -0.0034362 -0.0000040" rpy="0.0000000 -0.0000000 0.0000000" />
      <geometry>
        <sphere radius="0.0050913" />
        </geometry>
      </collision>
    </link>
  <link name="R_middle_mpp_link">
    <inertial>
      <origin xyz="0.01476009 -0.00171481 -0.00012869" rpy="0 0 0" />
      <mass value="0.01430214" />
      <inertia ixx="0.00000086" ixy="-0.00000003" ixz="0" iyy="0.00000344" iyz="0" izz="0.00000339" />
      </inertial>
    <visual>
      <origin xyz="0 0 0" rpy="0 0 0" />
      <geometry>
        <mesh filename="meshes/R_middle_mpp_link.STL" />
        </geometry>
      <material name="R_middle_mpp_link_visual_material_53">
        <color rgba="0.752941176470588 0.752941176470588 0.752941176470588 1" />
        </material>
      </visual>
    <collision name="simplified_capsule_body">
      <origin xyz="0.0118820 -0.0002624 -0.0005196" rpy="1.5649945 -1.1345098 -1.4426639" />
      <geometry>
        <cylinder radius="0.0080883" length="0.0378450" />
        </geometry>
      </collision>
    <collision name="simplified_capsule_a">
      <origin xyz="0.0306617 0.0020568 -0.0005660" rpy="0.0000000 -0.0000000 0.0000000" />
      <geometry>
        <sphere radius="0.0080883" />
        </geometry>
      </collision>
    <collision name="simplified_capsule_b">
      <origin xyz="-0.0068978 -0.0025816 -0.0004732" rpy="0.0000000 -0.0000000 0.0000000" />
      <geometry>
        <sphere radius="0.0080883" />
        </geometry>
      </collision>
    </link>
  <link name="R_middle_ip_link">
    <inertial>
      <origin xyz="0.01771317 -0.00109666 -0.0000256" rpy="0 0 0" />
      <mass value="0.0148881" />
      <inertia ixx="0.00000047" ixy="-0.00000038" ixz="0" iyy="0.00000344" iyz="0" izz="0.00000344" />
      </inertial>
    <visual>
      <origin xyz="0 0 0" rpy="0 0 0" />
      <geometry>
        <mesh filename="meshes/R_middle_ip_link.STL" />
        </geometry>
      <material name="R_middle_ip_link_visual_material_54">
        <color rgba="0.752941176470588 0.752941176470588 0.752941176470588 1" />
        </material>
      </visual>
    <collision name="simplified_capsule_body">
      <origin xyz="0.0189099 0.0002952 -0.0000437" rpy="-1.5621708 -1.5544165 1.7476926" />
      <geometry>
        <cylinder radius="0.0053169" length="0.0378637" />
        </geometry>
      </collision>
    <collision name="simplified_capsule_a">
      <origin xyz="0.0375169 0.0037873 -0.0000464" rpy="0.0000000 -0.0000000 0.0000000" />
      <geometry>
        <sphere radius="0.0053169" />
        </geometry>
      </collision>
    <collision name="simplified_capsule_b">
      <origin xyz="0.0003029 -0.0031970 -0.0000410" rpy="0.0000000 -0.0000000 0.0000000" />
      <geometry>
        <sphere radius="0.0053169" />
        </geometry>
      </collision>
    </link>
  <link name="R_ring_mpp_link">
    <inertial>
      <origin xyz="0.01475954 -0.00171495 -0.00012869" rpy="0 0 0" />
      <mass value="0.01430214" />
      <inertia ixx="0.00000086" ixy="-0.00000003" ixz="0" iyy="0.00000344" iyz="0" izz="0.00000339" />
      </inertial>
    <visual>
      <origin xyz="0 0 0" rpy="0 0 0" />
      <geometry>
        <mesh filename="meshes/R_ring_mpp_link.STL" />
        </geometry>
      <material name="R_ring_mpp_link_visual_material_55">
        <color rgba="0.752941176470588 0.752941176470588 0.752941176470588 1" />
        </material>
      </visual>
    <collision name="simplified_capsule_body">
      <origin xyz="0.0118697 -0.0002624 0.0000016" rpy="1.5198306 -1.1316436 -1.4017567" />
      <geometry>
        <cylinder radius="0.0080883" length="0.0378450" />
        </geometry>
      </collision>
    <collision name="simplified_capsule_a">
      <origin xyz="0.0306450 0.0020568 -0.0004082" rpy="0.0000000 -0.0000000 0.0000000" />
      <geometry>
        <sphere radius="0.0080883" />
        </geometry>
      </collision>
    <collision name="simplified_capsule_b">
      <origin xyz="-0.0069056 -0.0025816 0.0004115" rpy="0.0000000 -0.0000000 0.0000000" />
      <geometry>
        <sphere radius="0.0080883" />
        </geometry>
      </collision>
    </link>
  <link name="R_ring_ip_link">
    <inertial>
      <origin xyz="0.01615432 -0.00130235 -0.00002763" rpy="0 0 0" />
      <mass value="0.01374794" />
      <inertia ixx="0.00000043" ixy="-0.00000033" ixz="0" iyy="0.00000282" iyz="0" izz="0.00000281" />
      </inertial>
    <visual>
      <origin xyz="0 0 0" rpy="0 0 0" />
      <geometry>
        <mesh filename="meshes/R_ring_ip_link.STL" />
        </geometry>
      <material name="R_ring_ip_link_visual_material_56">
        <color rgba="0.752941176470588 0.752941176470588 0.752941176470588 1" />
        </material>
      </visual>
    <collision name="simplified_capsule_body">
      <origin xyz="0.0174140 -0.0000459 -0.0000026" rpy="-1.7203435 -1.5702529 1.9115170" />
      <geometry>
        <cylinder radius="0.0050913" length="0.0356850" />
        </geometry>
      </collision>
    <collision name="simplified_capsule_a">
      <origin xyz="0.0349315 0.0033443 -0.0000011" rpy="0.0000000 -0.0000000 0.0000000" />
      <geometry>
        <sphere radius="0.0050913" />
        </geometry>
      </collision>
    <collision name="simplified_capsule_b">
      <origin xyz="-0.0001034 -0.0034362 -0.0000040" rpy="0.0000000 -0.0000000 0.0000000" />
      <geometry>
        <sphere radius="0.0050913" />
        </geometry>
      </collision>
    </link>
  <link name="R_little_mpp_link">
    <inertial>
      <origin xyz="0.0147588 -0.00171514 -0.00012869" rpy="0 0 0" />
      <mass value="0.01430214" />
      <inertia ixx="0.00000086" ixy="-0.00000003" ixz="0" iyy="0.00000344" iyz="0" izz="0.00000339" />
      </inertial>
    <visual>
      <origin xyz="0 0 0" rpy="0 0 0" />
      <geometry>
        <mesh filename="meshes/R_little_mpp_link.STL" />
        </geometry>
      <material name="R_little_mpp_link_visual_material_57">
        <color rgba="0.752941176470588 0.752941176470588 0.752941176470588 1" />
        </material>
      </visual>
    <collision name="simplified_capsule_body">
      <origin xyz="0.0118697 -0.0002624 0.0000016" rpy="1.5198306 -1.1316436 -1.4017567" />
      <geometry>
        <cylinder radius="0.0080883" length="0.0378450" />
        </geometry>
      </collision>
    <collision name="simplified_capsule_a">
      <origin xyz="0.0306450 0.0020568 -0.0004082" rpy="0.0000000 -0.0000000 0.0000000" />
      <geometry>
        <sphere radius="0.0080883" />
        </geometry>
      </collision>
    <collision name="simplified_capsule_b">
      <origin xyz="-0.0069056 -0.0025816 0.0004115" rpy="0.0000000 -0.0000000 0.0000000" />
      <geometry>
        <sphere radius="0.0080883" />
        </geometry>
      </collision>
    </link>
  <link name="R_little_ip_link">
    <inertial>
      <origin xyz="0.01303327 -0.00143438 -0.0000295" rpy="0 0 0" />
      <mass value="0.01179268" />
      <inertia ixx="0.00000034" ixy="-0.00000023" ixz="0" iyy="0.00000179" iyz="0" izz="0.00000178" />
      </inertial>
    <visual>
      <origin xyz="0 0 0" rpy="0 0 0" />
      <geometry>
        <mesh filename="meshes/R_little_ip_link.STL" />
        </geometry>
      <material name="R_little_ip_link_visual_material_58">
        <color rgba="0.752941176470588 0.752941176470588 0.752941176470588 1" />
        </material>
      </visual>
    <collision name="simplified_capsule_body">
      <origin xyz="0.0135435 -0.0005189 -0.0000155" rpy="1.4975177 -1.3591171 -1.2728070" />
      <geometry>
        <cylinder radius="0.0049729" length="0.0293997" />
        </geometry>
      </collision>
    <collision name="simplified_capsule_a">
      <origin xyz="0.0278667 0.0027796 -0.0002416" rpy="0.0000000 -0.0000000 0.0000000" />
      <geometry>
        <sphere radius="0.0049729" />
        </geometry>
      </collision>
    <collision name="simplified_capsule_b">
      <origin xyz="-0.0007798 -0.0038173 0.0002106" rpy="0.0000000 -0.0000000 0.0000000" />
      <geometry>
        <sphere radius="0.0049729" />
        </geometry>
      </collision>
    </link>
  <joint name="R_palm_joint" type="fixed">
    <origin xyz="0.00035702 -0.013196 0.099778" rpy="1.5708 -1.5708 0" />
    <parent link="R_hand_base_link" />
    <child link="R_palm_link" />
    <axis xyz="0 0 0" />
    </joint>
  <joint name="R_thumb_cmp_joint" type="revolute">
    <origin xyz="-0.048578 -0.028956 -0.0073648" rpy="1.5708 -0.75224 -1.5708" />
    <parent link="R_palm_link" />
    <child link="R_thumb_cmp_link" />
    <axis xyz="0 0 1" />
    <limit lower="0" upper="0.96" effort="1.35" velocity="2.09" />
    <dynamics damping="2.0" friction="0.02" /></joint>
  <joint name="R_thumb_mpp_joint" type="revolute">
    <origin xyz="0.012 0.0010557 -0.010045" rpy="-1.4661 -0.00015422 -1.621E-05" />
    <parent link="R_thumb_cmp_link" />
    <child link="R_thumb_mpp_link" />
    <axis xyz="0 0 1" />
    <limit lower="0" upper="1.04" effort="1.35" velocity="2.09" />
    <dynamics damping="2.0" friction="0.02" /></joint>
  <joint name="R_thumb_ip_joint" type="revolute">
    <origin xyz="0.075 0 0" rpy="0 0 0.012082" />
    <parent link="R_thumb_mpp_link" />
    <child link="R_thumb_ip_link" />
    <axis xyz="0 0 1" />
    <limit lower="0" upper="1.05" effort="1.35" velocity="2.09" />
    <dynamics damping="2.0" friction="0.02" /></joint>
  <joint name="R_index_mpp_joint" type="revolute">
    <origin xyz="0.041818 -0.03077 -0.011696" rpy="1.5708 -0.18118 -0.020071" />
    <parent link="R_palm_link" />
    <child link="R_index_mpp_link" />
    <axis xyz="0 0 1" />
    <limit lower="0" upper="1.46" effort="1.35" velocity="2.09" />
    <dynamics damping="2.0" friction="0.02" /></joint>
  <joint name="R_index_ip_joint" type="revolute">
    <origin xyz="0.0388 0 0" rpy="0 0 -0.014509" />
    <parent link="R_index_mpp_link" />
    <child link="R_index_ip_link" />
    <axis xyz="0 0 1" />
    <limit lower="0" upper="1.62" effort="1.35" velocity="2.09" />
    <dynamics damping="2.0" friction="0.02" /></joint>
  <joint name="R_middle_mpp_joint" type="revolute">
    <origin xyz="0.042022 -0.011107 -0.011696" rpy="1.5673 -0.18114 0.019678" />
    <parent link="R_palm_link" />
    <child link="R_middle_mpp_link" />
    <axis xyz="0 0 1" />
    <limit lower="0" upper="1.46" effort="1.35" velocity="2.09" />
    <dynamics damping="2.0" friction="0.02" /></joint>
  <joint name="R_middle_ip_joint" type="revolute">
    <origin xyz="0.038807 0 0" rpy="0.00023357 -0.019354 -0.012068" />
    <parent link="R_middle_mpp_link" />
    <child link="R_middle_ip_link" />
    <axis xyz="0 0 1" />
    <limit lower="0" upper="1.62" effort="1.35" velocity="2.09" />
    <dynamics damping="2.0" friction="0.02" /></joint>
  <joint name="R_ring_mpp_joint" type="revolute">
    <origin xyz="0.041818 0.010057 -0.011696" rpy="1.5708 -0.18118 0.020071" />
    <parent link="R_palm_link" />
    <child link="R_ring_mpp_link" />
    <axis xyz="0 0 1" />
    <limit lower="0" upper="1.46" effort="1.35" velocity="2.09" />
    <dynamics damping="2.0" friction="0.02" /></joint>
  <joint name="R_ring_ip_joint" type="revolute">
    <origin xyz="0.0388 0 0" rpy="0 0 -0.014509" />
    <parent link="R_ring_mpp_link" />
    <child link="R_ring_ip_link" />
    <axis xyz="0 0 1" />
    <limit lower="0" upper="1.62" effort="1.35" velocity="2.09" />
    <dynamics damping="2.0" friction="0.02" /></joint>
  <joint name="R_little_mpp_joint" type="revolute">
    <origin xyz="0.041203 0.030462 -0.011696" rpy="1.5708 -0.18118 0.040143" />
    <parent link="R_palm_link" />
    <child link="R_little_mpp_link" />
    <axis xyz="0 0 1" />
    <limit lower="0" upper="1.46" effort="1.35" velocity="2.09" />
    <dynamics damping="2.0" friction="0.02" /></joint>
  <joint name="R_little_ip_joint" type="revolute">
    <origin xyz="0.0388 0 0" rpy="0 0 -0.014509" />
    <parent link="R_little_mpp_link" />
    <child link="R_little_ip_link" />
    <axis xyz="0 0 1" />
    <limit lower="0" upper="1.62" effort="1.35" velocity="2.09" />
    <dynamics damping="2.0" friction="0.02" /></joint>
  </robot>